<robot
  name="propagator">
  <link
    name="base_link">
    <inertial>
      <origin
        xyz="-0.0415869726158866 -0.00625483966251392 -0.0213812300507671"
        rpy="0 0 0" />
      <mass
        value="39.863607133373" />
      <inertia
        ixx="3.82040417943905"
        ixy="-0.00762575911292515"
        ixz="0.935878421154655"
        iyy="11.533921351454"
        iyz="-0.000302008115647474"
        izz="13.8290501505245" />
    </inertial>
    <visual>
      <origin
        xyz="0 0 0"
        rpy="0 0 0" />
      <geometry>
        <mesh
          filename="package://propagator_description/meshes/base_link.STL" />
      </geometry>
      <material name="blue">
        <color rgba="0 0 1 .25" />
      </material>
    </visual>
    <collision>
      <origin
        xyz="0 0 0"
        rpy="0 0 0" />
      <geometry>
        <mesh
          filename="package://propagator_description/meshes/base_link.STL" />
      </geometry>
    </collision>
  </link>
  <link
    name="port_prop_housing">
    <inertial>
      <origin
        xyz="-0.00498963948244502 1.19458740479583E-05 0.0215390674937084"
        rpy="0 0 0" />
      <mass
        value="0.206624181342967" />
      <inertia
        ixx="0.00068454456545582"
        ixy="8.08174284626606E-08"
        ixz="-1.21489129963592E-05"
        iyy="0.000537480451235849"
        iyz="-8.59403927352897E-08"
        izz="0.000333382604559422" />
    </inertial>
    <visual>
      <origin
        xyz="0 0 0"
        rpy="0 0 0" />
      <geometry>
        <mesh
          filename="package://propagator_description/meshes/port_prop_housing.STL" />
      </geometry>
      <material name="red">
        <color
          rgba="1 0 0 .5" />
      </material>
    </visual>
    <collision>
      <origin
        xyz="0 0 0"
        rpy="0 0 0" />
      <geometry>
        <mesh
          filename="package://propagator_description/meshes/port_prop_housing.STL" />
      </geometry>
    </collision>
  </link>
  <joint
    name="port_servo"
    type="revolute">
    <origin
      xyz="-0.659192821211375 0.296562240929375 -0.345876978652672"
      rpy="4.01736136899036E-35 0 0" />
    <parent
      link="base_link" />
    <child
      link="port_prop_housing" />
    <axis
      xyz="0 0 1" />
      <limit lower="0" upper="6.283185" velocity="6.597344565" effort="6.0" />
  </joint>
  <link
    name="port_propeller">
    <inertial>
      <origin
        xyz="0.00048182 -1.2442E-06 2.894E-05"
        rpy="0 0 0" />
      <mass
        value="0.039686" />
      <inertia
        ixx="7.834E-05"
        ixy="-3.2019E-10"
        ixz="-2.3552E-06"
        iyy="4.1887E-05"
        iyz="1.4746E-10"
        izz="4.2037E-05" />
    </inertial>
    <visual>
      <origin
        xyz="0 0 0"
        rpy="0 0 0" />
      <geometry>
        <mesh
          filename="package://propagator_description/meshes/port_propeller.STL" />
      </geometry>
      <material name="red">
      </material>
    </visual>
    <collision>
      <origin
        xyz="0 0 0"
        rpy="0 0 0" />
      <geometry>
        <mesh
          filename="package://propagator_description/meshes/port_propeller.STL" />
      </geometry>
    </collision>
  </link>
  <joint
    name="port_housing_to_prop"
    type="prismatic">
    <origin
      xyz="-0.000691858234449394 0 -4.4696283903245E-05"
      rpy="4.01736136899036E-35 0 0" />
    <parent
      link="port_prop_housing" />
    <child
      link="port_propeller" />
    <axis
      xyz="-1 0 0" />
      <limit lower="0" upper="1" velocity="1" effort="1" />
  </joint>
  <link
    name="starboard_prop_housing">
    <inertial>
      <origin
        xyz="-0.0049896 1.2213E-05 0.021539"
        rpy="0 0 0" />
      <mass
        value="0.20662" />
      <inertia
        ixx="0.00068454"
        ixy="8.0542E-08"
        ixz="-1.2149E-05"
        iyy="0.00053748"
        iyz="-8.4831E-08"
        izz="0.00033338" />
    </inertial>
    <visual>
      <origin
        xyz="0 0 0"
        rpy="0 0 0" />
      <geometry>
        <mesh
          filename="package://propagator_description/meshes/starboard_prop_housing.STL" />
      </geometry>
      <material name="green">
        <color rgba="0 1 0 .5" />
      </material>
    </visual>
    <collision>
      <origin
        xyz="0 0 0"
        rpy="0 0 0" />
      <geometry>
        <mesh
          filename="package://propagator_description/meshes/starboard_prop_housing.STL" />
      </geometry>
    </collision>
  </link>
  <joint
    name="starboard_servo"
    type="revolute">
    <origin
      xyz="-0.659192821211375 -0.312118124727417 -0.345876978652668"
      rpy="4.01736136899036E-35 0 0" />
    <parent
      link="base_link" />
    <child
      link="starboard_prop_housing" />
    <axis
      xyz="0 0 1" />
      <limit lower="0" upper="6.283185" velocity="6.597344565" effort="6.0" />
  </joint>
  <link
    name="starboard_propeller">
    <inertial>
      <origin
        xyz="0.00048182 -1.2442E-06 2.894E-05"
        rpy="0 0 0" />
      <mass
        value="0.039686" />
      <inertia
        ixx="7.834E-05"
        ixy="-3.2019E-10"
        ixz="-2.3552E-06"
        iyy="4.1887E-05"
        iyz="1.4746E-10"
        izz="4.2037E-05" />
    </inertial>
    <visual>
      <origin
        xyz="0 0 0"
        rpy="0 0 0" />
      <geometry>
        <mesh
          filename="package://propagator_description/meshes/starboard_propeller.STL" />
      </geometry>
      <material name="green">
      </material>
    </visual>
    <collision>
      <origin
        xyz="0 0 0"
        rpy="0 0 0" />
      <geometry>
        <mesh
          filename="package://propagator_description/meshes/starboard_propeller.STL" />
      </geometry>
    </collision>
  </link>
  <joint
    name="starboard_housing_to_prop"
    type="prismatic">
    <origin
      xyz="-0.000691858234449505 0 -4.46962839034115E-05"
      rpy="4.01736136899036E-35 0 0" />
    <parent
      link="starboard_prop_housing" />
    <child
      link="starboard_propeller" />
    <axis
      xyz="-1 0 0" />
    <limit lower="0" upper="1" velocity="1" effort="1" />
  </joint>
  <link
    name="lidar">
    <inertial>
      <origin
        xyz="0.0592107824998666 0.0527713136518488 -0.0249291589313144"
        rpy="0 0 3.14159" />
      <mass
        value="1.29594590979252" />
      <inertia
        ixx="0.00314879199623082"
        ixy="-1.74282951480328E-07"
        ixz="-4.15021660215941E-07"
        iyy="0.00323945410310953"
        iyz="4.61557976596404E-05"
        izz="0.00217323763280054" />
    </inertial>
    <visual>
      <origin
        xyz="0 0 0"
        rpy="0 0 0" />
      <geometry>
        <mesh
          filename="package://propagator_description/meshes/lidar.STL" />
      </geometry>
      <material
        name="">
        <color
          rgba="0.792156862745098 0.819607843137255 0.933333333333333 1" />
      </material>
    </visual>
    <collision>
      <origin
        xyz="0 0 0"
        rpy="0 0 0" />
      <geometry>
        <mesh
          filename="package://propagator_description/meshes/lidar.STL" />
      </geometry>
    </collision>
  </link>
  <joint
    name="lidar_servo"
    type="fixed">
    <origin
      xyz="0.645299789819263 -0.0669769690222898 0.27477134491897"
      rpy="-2.94943335198801 3.24078283203981E-05 1.57062975690281" />
    <parent
      link="base_link" />
    <child
      link="lidar" />
    <axis
      xyz="0 0 0" />
  </joint>
</robot>
