<robot
  name="propagator_description">
  <link
    name="base_link">
    <inertial>
      <origin
        xyz="0.53557 -0.0088755 0.25419"
        rpy="0 0 0" />
      <mass
        value="0.0079272" />
      <inertia
        ixx="1.165E-05"
        ixy="-4.7493E-08"
        ixz="-8.8369E-15"
        iyy="7.7709E-07"
        iyz="3.1429E-14"
        izz="1.2419E-05" />
    </inertial>
    <visual>
      <origin
        xyz="0 0 0"
        rpy="0 0 0" />
      <geometry>
        <mesh
          filename="package://propagator_description/meshes/base_link.STL" />
      </geometry>
      <material
        name="blue">
        <color
          rgba="0 0 1 .125" />
      </material>
    </visual>
    <collision>
      <origin
        xyz="0 0 0"
        rpy="0 0 0" />
      <geometry>
        <mesh
          filename="package://propagator_description/meshes/base_link.STL" />
      </geometry>
    </collision>
  </link>
  <link
    name="port_prop_housing">
    <inertial>
      <origin
        xyz="-0.0049896 1.1946E-05 0.021539"
        rpy="0 0 0" />
      <mass
        value="0.20662" />
      <inertia
        ixx="0.00068454"
        ixy="8.0817E-08"
        ixz="-1.2149E-05"
        iyy="0.00053748"
        iyz="-8.594E-08"
        izz="0.00033338" />
    </inertial>
    <visual>
      <origin
        xyz="0 0 0"
        rpy="0 0 0" />
      <geometry>
        <mesh
          filename="package://propagator_description/meshes/port_prop_housing.STL" />
      </geometry>
      <material
        name="red">
        <color
          rgba="1 0 0 0.5" />
      </material>
    </visual>
    <collision>
      <origin
        xyz="0 0 0"
        rpy="0 0 0" />
      <geometry>
        <mesh
          filename="package://propagator_description/meshes/port_prop_housing.STL" />
      </geometry>
    </collision>
  </link>
  <joint
    name="port_servo"
    type="revolute">
    <origin
      xyz="-0.65919 0.29656 -0.34588"
      rpy="4.0174E-35 0 0" />
    <parent
      link="base_link" />
    <child
      link="port_prop_housing" />
    <axis
      xyz="0 0 1" />
    <limit
      lower="0"
      upper="6.2832"
      effort="6"
      velocity="6.5973" />
  </joint>
  <link
    name="port_propeller">
    <inertial>
      <origin
        xyz="0.00048182 -1.2442E-06 2.894E-05"
        rpy="0 0 0" />
      <mass
        value="0.039686" />
      <inertia
        ixx="7.834E-05"
        ixy="-3.2019E-10"
        ixz="-2.3552E-06"
        iyy="4.1887E-05"
        iyz="1.4746E-10"
        izz="4.2037E-05" />
    </inertial>
    <visual>
      <origin
        xyz="0 0 0"
        rpy="0 0 0" />
      <geometry>
        <mesh
          filename="package://propagator_description/meshes/port_propeller.STL" />
      </geometry>
      <material
        name="red">
        <color
          rgba="1 0 0 0.5" />
      </material>
    </visual>
    <collision>
      <origin
        xyz="0 0 0"
        rpy="0 0 0" />
      <geometry>
        <mesh
          filename="package://propagator_description/meshes/port_propeller.STL" />
      </geometry>
    </collision>
  </link>
  <joint
    name="port_housing_to_prop"
    type="prismatic">
    <origin
      xyz="-0.00069186 0 -4.4696E-05"
      rpy="4.0174E-35 0 0" />
    <parent
      link="port_prop_housing" />
    <child
      link="port_propeller" />
    <axis
      xyz="-1 0 0" />
    <limit
      lower="0"
      upper="1"
      effort="1"
      velocity="1" />
  </joint>
  <link
    name="starboard_prop_housing">
    <inertial>
      <origin
        xyz="-0.0049896 1.2213E-05 0.021539"
        rpy="0 0 0" />
      <mass
        value="0.20662" />
      <inertia
        ixx="0.00068454"
        ixy="8.0542E-08"
        ixz="-1.2149E-05"
        iyy="0.00053748"
        iyz="-8.4831E-08"
        izz="0.00033338" />
    </inertial>
    <visual>
      <origin
        xyz="0 0 0"
        rpy="0 0 0" />
      <geometry>
        <mesh
          filename="package://propagator_description/meshes/starboard_prop_housing.STL" />
      </geometry>
      <material
        name="green">
        <color
          rgba="0 1 0 0.5" />
      </material>
    </visual>
    <collision>
      <origin
        xyz="0 0 0"
        rpy="0 0 0" />
      <geometry>
        <mesh
          filename="package://propagator_description/meshes/starboard_prop_housing.STL" />
      </geometry>
    </collision>
  </link>
  <joint
    name="starboard_servo"
    type="revolute">
    <origin
      xyz="-0.65919 -0.31212 -0.34588"
      rpy="4.0174E-35 0 0" />
    <parent
      link="base_link" />
    <child
      link="starboard_prop_housing" />
    <axis
      xyz="0 0 1" />
    <limit
      lower="0"
      upper="6.2832"
      effort="6"
      velocity="6.5973" />
  </joint>
  <link
    name="starboard_propeller">
    <inertial>
      <origin
        xyz="0.00048182 -1.2442E-06 2.894E-05"
        rpy="0 0 0" />
      <mass
        value="0.039686" />
      <inertia
        ixx="7.834E-05"
        ixy="-3.2019E-10"
        ixz="-2.3552E-06"
        iyy="4.1887E-05"
        iyz="1.4746E-10"
        izz="4.2037E-05" />
    </inertial>
    <visual>
      <origin
        xyz="0 0 0"
        rpy="0 0 0" />
      <geometry>
        <mesh
          filename="package://propagator_description/meshes/starboard_propeller.STL" />
      </geometry>
      <material
        name="green">
        <color
          rgba="0 1 0 0.5" />
      </material>
    </visual>
    <collision>
      <origin
        xyz="0 0 0"
        rpy="0 0 0" />
      <geometry>
        <mesh
          filename="package://propagator_description/meshes/starboard_propeller.STL" />
      </geometry>
    </collision>
  </link>
  <joint
    name="starboard_housing_to_prop"
    type="prismatic">
    <origin
      xyz="-0.000691858234449505 0 -4.46962839034115E-05"
      rpy="4.01736136899036E-35 0 0" />
    <parent
      link="starboard_prop_housing" />
    <child
      link="starboard_propeller" />
    <axis
      xyz="-1 0 0" />
    <limit lower="0" upper="1" velocity="1" effort="1" />
  </joint>
  <link
    name="lidar">
    <inertial>
      <origin
	xyz="0.0592107824998666 0.0527713136518488 -0.0249291589313144"
        rpy="0 0 0" />
      <mass
        value="1.29594590979252" />
      <inertia
        ixx="0.00314879199623082"
        ixy="-1.74282951480328E-07"
        ixz="-4.15021660215941E-07"
        iyy="0.00323945410310953"
        iyz="4.61557976596404E-05"
        izz="0.00217323763280054" />
    </inertial>
    <visual>
      <origin
        xyz="0 0 0"
        rpy="0 0 0" />
      <geometry>
        <mesh
          filename="package://propagator_description/meshes/lidar.STL" />
      </geometry>
      <material
        name="">
        <color
          rgba="0.792156862745098 0.819607843137255 0.933333333333333 1" />
      </material>
    </visual>
    <collision>
      <origin
        xyz="0 0 0"
        rpy="0 0 0" />
      <geometry>
        <mesh
          filename="package://propagator_description/meshes/lidar.STL" />
      </geometry>
    </collision>
  </link>

  <!-- Old rpy data
		rpy="-2.94943335198801 3.24078283203981E-05 1.57062975690281"-->
  <joint
    name="lidar_servo"
    type="fixed">
	
    <origin
      xyz="0.645299789819263 -0.0669769690222898 0.27477134491897"
      rpy="0 0 0" />
    <parent
      link="base_link" />
    <child
      link="lidar" />
    <axis
      xyz="0 0 0" />
  </joint>
  
  <!-- Now we will add facia lettering to the base_link of the boat -->
  <link name="port_lettering">
    <visual>
      <origin
        xyz="0 0 0"
        rpy="0 0 0" />
      <geometry>
        <mesh filename="package://propagator_description/meshes/port_lettering.STL" />
      </geometry>
      <material name="red"/>
    </visual>
    <collision>
      <origin
        xyz="0 0 0"
        rpy="0 0 0" />
      <geometry>
        <mesh filename="package://propagator_description/meshes/port_lettering.STL" />
      </geometry>
    </collision>
  </link>
  <joint name="base_link_to_port_lettering" type="fixed">
      <origin
        xyz="-.070 .435 -.045"
        rpy="0 3.019 0" />
      <parent link="base_link" />
      <child link="port_lettering" />
  </joint>
</robot>
